Workbook

Sheet Info
A1: Dataset | B1: Date Range | C1: Source | D1: Excluded dates | E1: Notes
A2: WHR | B2: 2015-2025 | C2: link
A3: My happiness dataset | B3: 7/2025-3/2026 | D3: 7/1/2025-7/3/2025; 1/5/2026-1/15/2026 | E3: US date format
A5: LookerStudio dashboard

Sheet raw_data
A1: Year | B1: Happiness Ranking | C1: Country | D1: Life evaluation | E1: Change | F1: Inequality | G1: Social support | H1: GDP per capita | I1: Healthy life expectancy | J1: Freedom | K1: Generosity | L1: Perception of corruption | M1: Positive emotions | N1: Negative emotions | O1: Donated | P1: Volunteered | Q1: Helped a stranger
A2: 2015 | B2: 1 | C2: Denmark | D2: 7.526 | E2: −0.167 | F2: 13 | G2: 5 | H2: 10 | I2: 21 | J2: 6 | K2: 14 | L2: 4 | M2: 11 | N2: 38 | O2: 14 | P2: 52 | Q2: 58
A3: 2015 | B3: 2 | C3: Switzerland | D3: 7.509 | E3: −0.141 | F3: 35 | G3: 13 | H3: 6 | I3: 12 | J3: 12 | K3: 23 | L3: 5 | M3: 17 | N3: 8 | O3: 23 | P3: 28 | Q3: 63
A4: 2015 | B4: 3 | C4: Iceland | D4: 7.501 | E4: 0.146 | F4: 21 | G4: 2 | H4: 12 | I4: 4 | J4: 7 | K4: 6 | L4: 27 | M4: 18 | N4: 16 | O4: 6 | P4: 46 | Q4: 75
A5: 2015 | B5: 4 | C5: Norway | D5: 7.498 | E5: −0.157 | F5: 19 | G5: 10 | H5: 4 | I5: 9 | J5: 4 | K5: 8 | L5: 8 | M5: 14 | N5: 34 | O5: 8 | P5: 25 | Q5: 73
A6: 2015 | B6: 5 | C6: Finland | D6: 7.413 | E6: 0.024 | F6: 9 | G6: 9 | H6: 21 | I6: 19 | J6: 11 | K6: 26 | L6: 6 | M6: 39 | N6: 22 | O6: 26 | P6: 27 | Q6: 51
A7: 2015 | B7: 6 | C7: Canada | D7: 7.404 | E7: −0.073 | F7: 12 | G7: 12 | H7: 18 | I7: 15 | J7: 10 | K7: 11 | L7: 15 | M7: 19 | N7: 78 | O7: 11 | P7: 14 | Q7: 22
A8: 2015 | B8: 7 | C8: Netherlands | D8: 7.339 | E8: −0.173 | F8: 1 | G8: 47 | H8: 9 | J8: 20 | K8: 9 | L8: 13 | M8: 36 | N8: 27 | O8: 9 | P8: 21 | Q8: 50
A9: 2015 | B9: 8 | C9: New Zealand | D9: 7.334 | E9: 0.113 | F9: 4 | G9: 1 | H9: 27 | I9: 27 | J9: 5 | K9: 5 | L9: 3 | M9: 16 | N9: 5 | O9: 5 | P9: 6 | Q9: 33
A10: 2015 | B10: 9 | C10: Australia | D10: 7.313 | E10: −0.037 | F10: 20 | G10: 8 | H10: 17 | I10: 16 | J10: 13 | K10: 3 | L10: 9 | M10: 29 | N10: 35 | O10: 3 | P10: 11 | Q10: 16
A11: 2015 | B11: 10 | C11: Sweden | D11: 7.291 | E11: −0.189 | F11: 15 | G11: 17 | H11: 14 | I11: 13 | J11: 8 | K11: 18 | L11: 7 | M11: 26 | N11: 21 | O11: 18 | P11: 96 | Q11: 45
A12: 2015 | B12: 11 | C12: Israel | D12: 7.267 | E12: −0.034 | F12: 32 | G12: 54 | H12: 32 | I12: 7 | J12: 79 | K12: 28 | L12: 61 | M12: 76 | N12: 60 | O12: 28 | P12: 50 | Q12: 81
A13: 2015 | B13: 12 | C13: Austria | D13: 7.119 | E13: −0.250 | F13: 27 | G13: 19 | H13: 11 | I13: 17 | J13: 22 | K13: 27 | L13: 20 | M13: 33 | N13: 7 | O13: 27 | P13: 43 | Q13: 71
A14: 2015 | B14: 13 | C14: United States | D14: 7.104 | E14: 0.022 | F14: 54 | G14: 35 | H14: 8 | I14: 54 | J14: 38 | K14: 13 | L14: 37 | M14: 24 | N14: 72 | O14: 13 | P14: 5 | Q14: 7
A15: 2015 | B15: 14 | C15: Costa Rica | D15: 7.087 | E15: −0.170 | F15: 104 | G15: 48 | H15: 56 | I15: 26 | J15: 19 | K15: 67 | L15: 52 | M15: 9 | N15: 79 | O15: 67 | P15: 56 | Q15: 35
A16: 2015 | B16: 17 | C16: Brazil | D16: 6.952 | E16: 0.103 | F16: 102 | G16: 33 | H16: 62 | I16: 75 | J16: 61 | K16: 60 | L16: 56 | M16: 58 | N16: 102 | O16: 60 | P16: 79 | Q16: 62
A17: 2015 | B17: 18 | C17: Belgium | D17: 6.929 | E17: −0.038 | F17: 6 | G17: 44 | H17: 15 | I17: 28 | J17: 30 | K17: 35 | L17: 17 | M17: 34 | N17: 52
A18: 2015 | B18: 19 | C18: Ireland | D18: 6.907 | E18: −0.169 | F18: 28 | G18: 7 | H18: 5 | I18: 20 | J18: 24 | K18: 10 | L18: 11 | M18: 32 | N18: 43 | O18: 10 | P18: 10 | Q18: 48
A19: 2015 | B19: 20 | C19: Luxembourg | D19: 6.871 | E19: −0.183 | F19: 5 | G19: 15 | H19: 1 | I19: 5 | J19: 9 | K19: 25 | L19: 10 | M19: 44 | N19: 24 | O19: 25 | P19: 26 | Q19: 126
A20: 2015 | B20: 21 | C20: Mexico | D20: 6.778 | E20: −0.310 | F20: 79 | G20: 96 | H20: 55 | I20: 63 | J20: 86 | K20: 106 | L20: 40 | M20: 51 | N20: 51 | O20: 106 | P20: 108 | Q20: 91
A21: 2015 | B21: 22 | C21: Singapore | D21: 6.739 | E21: 0.193 | F21: 11 | G21: 51 | H21: 3 | I21: 2 | J21: 26 | K21: 19 | L21: 2 | M21: 40 | N21: 4 | O21: 19 | P21: 54 | Q21: 80
A22: 2015 | B22: 23 | C22: United Kingdom | D22: 6.725 | E22: −0.158 | F22: 26 | G22: 14 | H22: 24 | I22: 29 | J22: 41 | K22: 7 | L22: 16 | M22: 37 | N22: 41 | O22: 7 | P22: 22 | Q22: 34
A23: 2015 | B23: 24 | C23: Chile | D23: 6.705 | E23: 0.118 | F23: 50 | G23: 70 | H23: 50 | I23: 32 | J23: 72 | K23: 43 | L23: 69 | M23: 28 | N23: 108 | O23: 43 | P23: 93 | Q23: 41
A24: 2015 | B24: 25 | C24: Panama | D24: 6.701 | E24: −0.442 | F24: 121 | G24: 45 | H24: 45 | I24: 36 | J24: 39 | K24: 46 | L24: 66 | M24: 22 | N24: 66 | O24: 46 | P24: 23 | Q24: 39
A25: 2015 | B25: 26 | C25: Argentina | D25: 6.65 | E25: 0.088 | F25: 53 | G25: 20 | H25: 49 | I25: 51 | J25: 29 | K25: 109 | L25: 90 | M25: 25 | N25: 91 | O25: 109 | P25: 67 | Q25: 69
A26: 2015 | B26: 27 | C26: Czechia | D26: 6.596 | E26: 0.306 | F26: 36 | G26: 28 | H26: 31 | I26: 35 | J26: 52 | K26: 84 | L26: 109 | M26: 57 | N26: 29 | O26: 84 | P26: 102 | Q26: 135
A27: 2015 | B27: 28 | C27: United Arab Emirates | D27: 6.573 | E27: −0.571 | F27: 73 | G27: 72 | H27: 7 | I27: 30 | J27: 15 | K27: 16 | L27: 46 | M27: 83 | N27: 16 | O27: 61 | P27: 10
A28: 2015 | B28: 29 | C28: Uruguay | D28: 6.545 | E28: 0.19 | F28: 87 | G28: 41 | H28: 48 | I28: 47 | J28: 14 | K28: 59 | L28: 33 | M28: 8 | N28: 85 | O28: 59 | P28: 62 | Q28: 37
A29: 2015 | B29: 30 | C29: Malta | D29: 6.488 | E29: 0.524 | F29: 42 | G29: 25 | H29: 26 | I29: 10 | J29: 16 | K29: 4 | L29: 30 | M29: 81 | N29: 119 | O29: 4 | P29: 36 | Q29: 87
A30: 2015 | B30: 31 | C30: Colombia | D30: 6.481 | E30: 0.065 | F30: 100 | G30: 42 | H30: 65 | I30: 39 | J30: 66 | K30: 90 | L30: 85 | M30: 10 | N30: 80 | O30: 90 | P30: 72 | Q30: 44
A31: 2015 | B31: 32 | C31: France | D31: 6.478 | E31: −0.286 | F31: 41 | G31: 38 | H31: 23 | I31: 14 | J31: 46 | K31: 75 | L31: 28 | M31: 38 | N31: 37 | O31: 75 | P31: 32 | Q31: 117
A32: 2015 | B32: 33 | C32: Thailand | D32: 6.474 | E32: 0.103 | F32: 31 | G32: 52 | H32: 61 | I32: 44 | J32: 27 | K32: 12 | L32: 121 | M32: 1 | N32: 13 | O32: 12 | P32: 83 | Q32: 99
A33: 2015 | B33: 34 | C33: Saudi Arabia | D33: 6.379 | E33: −0.101 | F33: 117 | G33: 75 | H33: 20 | I33: 56 | J33: 45 | K33: 45 | L33: 67 | M33: 103 | N33: 45 | O33: 97 | P33: 9
A34: 2015 | B34: 35 | C34: Taiwan Province of China | D34: 6.379 | E34: 0.158 | F34: 38 | G34: 43 | H34: 22 | J34: 91 | K34: 40 | L34: 93 | M34: 30 | N34: 2 | O34: 40 | P34: 82 | Q34: 46
A35: 2015 | B35: 36 | C35: Qatar | D35: 6.375 | E35: −0.291 | F35: 101 | H35: 2 | I35: 43
A36: 2015 | B36: 37 | C36: Spain | D36: 6.361 | E36: 0.039 | F36: 17 | G36: 6 | H36: 29 | I36: 6 | J36: 83 | K36: 57 | L36: 73 | M36: 52 | N36: 76
A37: 2015 | B37: 38 | C37: Algeria | D37: 6.355 | E37: 0.933
A38: 2015 | B38: 39 | C38: Guatemala | D38: 6.324 | E38: 0.359 | F38: 135 | G38: 74 | H38: 89 | I38: 90 | J38: 31 | K38: 51 | L38: 72 | M38: 5 | N38: 92 | O38: 51 | P38: 17 | Q38: 31
A39: 2015 | B39: 40 | C39: Suriname | D39: 6.269 | E39: 0
A40: 2015 | B40: 41 | C40: Kuwait | D40: 6.239 | E40: −0.276 | F40: 106 | G40: 73 | H40: 16 | I40: 22 | J40: 44 | K40: 29 | L40: 62 | M40: 101 | N40: 29 | O40: 92 | P40: 4
...

Sheet whr
A1: Year | B1: Happiness Ranking | C1: Country | D1: Region | E1: Subregion | F1: Intermediate-region | G1: Life evaluation | H1: Inequality | I1: Social support | J1: GDP per capita | K1: Healthy life expectancy | L1: Freedom | M1: Generosity | N1: Perception of corruption | O1: Positive emotions | P1: Negative emotions | Q1: Donated | R1: Volunteered | S1: Helped a stranger
A2: 2025 | B2: 1 | C2: Finland | D2: {=_xludf.XLOOKUP(C2,'country region mapping'!$A$2:$A$250, 'country region mapping'!$E$2:$E$250)} -> #NAME? | E2: {=_xludf.XLOOKUP(C2,'country region mapping'!$A$2:$A$267,'country region mapping'!$F$2:$F$267)} -> #NAME? | F2: {=_xludf.XLOOKUP(C2,'country region mapping'!$A$2:$A$267,'country region mapping'!$G$2:$G$267)} -> #NAME? | G2: 7.764 | H2: 2 | I2: 9 | J2: 17 | K2: 18 | L2: 11 | M2: 46 | N2: 2 | O2: 39 | P2: 11 | Q2: 46 | R2: 71 | S2: 96
A3: 2025 | B3: 2 | C3: Iceland | D3: {=_xludf.XLOOKUP(C3,'country region mapping'!$A$2:$A$250, 'country region mapping'!$E$2:$E$250)} -> #NAME? | E3: {=_xludf.XLOOKUP(C3,'country region mapping'!$A$2:$A$267,'country region mapping'!$F$2:$F$267)} -> #NAME? | F3: {=_xludf.XLOOKUP(C3,'country region mapping'!$A$2:$A$267,'country region mapping'!$G$2:$G$267)} -> #NAME? | G3: 7.54 | H3: 4 | I3: 1 | J3: 9 | K3: 4 | L3: 5 | M3: 8 | N3: 28 | O3: 7 | P3: 8 | Q3: 8 | R3: 78 | S3: 118
A4: 2025 | B4: 3 | C4: Denmark | D4: {=_xludf.XLOOKUP(C4,'country region mapping'!$A$2:$A$250, 'country region mapping'!$E$2:$E$250)} -> #NAME? | E4: {=_xludf.XLOOKUP(C4,'country region mapping'!$A$2:$A$267,'country region mapping'!$F$2:$F$267)} -> #NAME? | F4: {=_xludf.XLOOKUP(C4,'country region mapping'!$A$2:$A$267,'country region mapping'!$G$2:$G$267)} -> #NAME? | G4: 7.539 | H4: 13 | I4: 2 | J4: 6 | K4: 15 | L4: 17 | M4: 27 | N4: 3 | O4: 11 | P4: 41 | Q4: 27 | R4: 43 | S4: 61
A5: 2025 | B5: 4 | C5: Costa Rica | D5: {=_xludf.XLOOKUP(C5,'country region mapping'!$A$2:$A$250, 'country region mapping'!$E$2:$E$250)} -> #NAME? | E5: {=_xludf.XLOOKUP(C5,'country region mapping'!$A$2:$A$267,'country region mapping'!$F$2:$F$267)} -> #NAME? | F5: {=_xludf.XLOOKUP(C5,'country region mapping'!$A$2:$A$267,'country region mapping'!$G$2:$G$267)} -> #NAME? | G5: 7.439 | H5: 37 | I5: 30 | J5: 49 | K5: 29 | L5: 3 | M5: 90 | N5: 52 | O5: 5 | P5: 24 | Q5: 90 | R5: 75 | S5: 16
A6: 2025 | B6: 5 | C6: Sweden | D6: {=_xludf.XLOOKUP(C6,'country region mapping'!$A$2:$A$250, 'country region mapping'!$E$2:$E$250)} -> #NAME? | E6: {=_xludf.XLOOKUP(C6,'country region mapping'!$A$2:$A$267,'country region mapping'!$F$2:$F$267)} -> #NAME? | F6: {=_xludf.XLOOKUP(C6,'country region mapping'!$A$2:$A$267,'country region mapping'!$G$2:$G$267)} -> #NAME? | G6: 7.255 | H6: 7 | I6: 11 | J6: 10 | K6: 7 | L6: 20 | M6: 17 | N6: 4 | O6: 53 | P6: 36 | Q6: 17 | R6: 97 | S6: 80
A7: 2025 | B7: 6 | C7: Norway | D7: {=_xludf.XLOOKUP(C7,'country region mapping'!$A$2:$A$250, 'country region mapping'!$E$2:$E$250)} -> #NAME? | E7: {=_xludf.XLOOKUP(C7,'country region mapping'!$A$2:$A$267,'country region mapping'!$F$2:$F$267)} -> #NAME? | F7: {=_xludf.XLOOKUP(C7,'country region mapping'!$A$2:$A$267,'country region mapping'!$G$2:$G$267)} -> #NAME? | G7: 7.242 | H7: 9 | I7: 3 | J7: 3 | K7: 5 | L7: 9 | M7: 10 | N7: 8 | O7: 17 | P7: 34 | Q7: 10 | R7: 24 | S7: 83
A8: 2025 | B8: 7 | C8: Netherlands | D8: {=_xludf.XLOOKUP(C8,'country region mapping'!$A$2:$A$267,'country region mapping'!$E$2:$E$267)} -> #NAME? | E8: {=_xludf.XLOOKUP(C8,'country region mapping'!$A$2:$A$267,'country region mapping'!$F$2:$F$267)} -> #NAME? | F8: {=_xludf.XLOOKUP(C8,'country region mapping'!$A$2:$A$267,'country region mapping'!$G$2:$G$267)} -> #NAME? | G8: 7.223 | H8: 1 | I8: 25 | J8: 7 | L8: 32 | M8: 7 | N8: 13 | O8: 47 | P8: 31 | Q8: 7 | R8: 22 | S8: 104
A9: 2025 | B9: 8 | C9: Israel | D9: {=_xludf.XLOOKUP(C9,'country region mapping'!$A$2:$A$250, 'country region mapping'!$E$2:$E$250)} -> #NAME? | E9: {=_xludf.XLOOKUP(C9,'country region mapping'!$A$2:$A$267,'country region mapping'!$F$2:$F$267)} -> #NAME? | F9: {=_xludf.XLOOKUP(C9,'country region mapping'!$A$2:$A$267,'country region mapping'!$G$2:$G$267)} -> #NAME? | G9: 7.187 | H9: 5 | I9: 18 | J9: 26 | K9: 9 | L9: 95 | M9: 44 | N9: 34 | O9: 108 | P9: 40 | Q9: 44 | R9: 65 | S9: 107
A10: 2025 | B10: 9 | C10: Luxembourg | D10: {=_xludf.XLOOKUP(C10,'country region mapping'!$A$2:$A$250, 'country region mapping'!$E$2:$E$250)} -> #NAME? | E10: {=_xludf.XLOOKUP(C10,'country region mapping'!$A$2:$A$267,'country region mapping'!$F$2:$F$267)} -> #NAME? | F10: {=_xludf.XLOOKUP(C10,'country region mapping'!$A$2:$A$267,'country region mapping'!$G$2:$G$267)} -> #NAME? | G10: 7.063 | H10: 20 | I10: 37 | J10: 2 | L10: 22 | M10: 32 | N10: 9 | O10: 43 | P10: 51 | Q10: 32 | R10: 36 | S10: 110
A11: 2025 | B11: 10 | C11: Switzerland | D11: {=_xludf.XLOOKUP(C11,'country region mapping'!$A$2:$A$250, 'country region mapping'!$E$2:$E$250)} -> #NAME? | E11: {=_xludf.XLOOKUP(C11,'country region mapping'!$A$2:$A$267,'country region mapping'!$F$2:$F$267)} -> #NAME? | F11: {=_xludf.XLOOKUP(C11,'country region mapping'!$A$2:$A$267,'country region mapping'!$G$2:$G$267)} -> #NAME? | G11: 7.018 | H11: 28 | I11: 28 | J11: 4 | K11: 6 | L11: 35 | M11: 14 | N11: 5 | O11: 27 | P11: 29 | Q11: 14 | R11: 34 | S11: 116
A12: 2025 | B12: 11 | C12: New Zealand | D12: {=_xludf.XLOOKUP(C12,'country region mapping'!$A$2:$A$250, 'country region mapping'!$E$2:$E$250)} -> #NAME? | E12: {=_xludf.XLOOKUP(C12,'country region mapping'!$A$2:$A$267,'country region mapping'!$F$2:$F$267)} -> #NAME? | F12: {=_xludf.XLOOKUP(C12,'country region mapping'!$A$2:$A$267,'country region mapping'!$G$2:$G$267)} -> #NAME? | G12: 6.995 | H12: 15 | I12: 10 | J12: 25 | K12: 17 | L12: 18 | M12: 13 | N12: 6 | O12: 14 | P12: 37 | Q12: 13 | R12: 11 | S12: 38
A13: 2025 | B13: 12 | C13: Mexico | D13: {=_xludf.XLOOKUP(C13,'country region mapping'!$A$2:$A$250, 'country region mapping'!$E$2:$E$250)} -> #NAME? | E13: {=_xludf.XLOOKUP(C13,'country region mapping'!$A$2:$A$267,'country region mapping'!$F$2:$F$267)} -> #NAME? | F13: {=_xludf.XLOOKUP(C13,'country region mapping'!$A$2:$A$267,'country region mapping'!$G$2:$G$267)} -> #NAME? | G13: 6.972 | H13: 63 | I13: 66 | J13: 59 | K13: 79 | L13: 36 | M13: 104 | N13: 54 | O13: 9 | P13: 26 | Q13: 104 | R13: 74 | S13: 68
A14: 2025 | B14: 13 | C14: Ireland | D14: {=_xludf.XLOOKUP(C14,'country region mapping'!$A$2:$A$250, 'country region mapping'!$E$2:$E$250)} -> #NAME? | E14: {=_xludf.XLOOKUP(C14,'country region mapping'!$A$2:$A$267,'country region mapping'!$F$2:$F$267)} -> #NAME? | F14: {=_xludf.XLOOKUP(C14,'country region mapping'!$A$2:$A$267,'country region mapping'!$G$2:$G$267)} -> #NAME? | G14: 6.928 | H14: 41 | I14: 21 | J14: 1 | K14: 16 | L14: 33 | M14: 6 | N14: 12 | O14: 44 | P14: 49 | Q14: 6 | R14: 16 | S14: 41
A15: 2025 | B15: 14 | C15: Belgium | D15: {=_xludf.XLOOKUP(C15,'country region mapping'!$A$2:$A$250, 'country region mapping'!$E$2:$E$250)} -> #NAME? | E15: {=_xludf.XLOOKUP(C15,'country region mapping'!$A$2:$A$267,'country region mapping'!$F$2:$F$267)} -> #NAME? | F15: {=_xludf.XLOOKUP(C15,'country region mapping'!$A$2:$A$267,'country region mapping'!$G$2:$G$267)} -> #NAME? | G15: 6.926 | H15: 10 | I15: 23 | J15: 12 | K15: 20 | L15: 66 | M15: 35 | N15: 20 | O15: 46 | P15: 68 | Q15: 35 | R15: 56 | S15: 101
A16: 2025 | B16: 15 | C16: Australia | D16: {=_xludf.XLOOKUP(C16,'country region mapping'!$A$2:$A$250, 'country region mapping'!$E$2:$E$250)} -> #NAME? | E16: {=_xludf.XLOOKUP(C16,'country region mapping'!$A$2:$A$267,'country region mapping'!$F$2:$F$267)} -> #NAME? | F16: {=_xludf.XLOOKUP(C16,'country region mapping'!$A$2:$A$267,'country region mapping'!$G$2:$G$267)} -> #NAME? | G16: 6.916 | H16: 33 | I16: 29 | J16: 16 | K16: 12 | L16: 44 | M16: 9 | N16: 17 | O16: 45 | P16: 65 | Q16: 9 | R16: 17 | S16: 37
A17: 2025 | B17: 16 | C17: Kosovo | D17: {=_xludf.XLOOKUP(C17,'country region mapping'!$A$2:$A$267,'country region mapping'!$E$2:$E$267)} -> #NAME? | E17: {=_xludf.XLOOKUP(C17,'country region mapping'!$A$2:$A$267,'country region mapping'!$F$2:$F$267)} -> #NAME? | F17: {=_xludf.XLOOKUP(C17,'country region mapping'!$A$2:$A$267,'country region mapping'!$G$2:$G$267)} -> #NAME? | G17: 6.91 | H17: 86 | I17: 62 | J17: 68 | L17: 21 | M17: 22 | N17: 117 | O17: 98 | P17: 16 | Q17: 22 | R17: 135 | S17: 74
A18: 2025 | B18: 17 | C18: Germany | D18: {=_xludf.XLOOKUP(C18,'country region mapping'!$A$2:$A$250, 'country region mapping'!$E$2:$E$250)} -> #NAME? | E18: {=_xludf.XLOOKUP(C18,'country region mapping'!$A$2:$A$267,'country region mapping'!$F$2:$F$267)} -> #NAME? | F18: {=_xludf.XLOOKUP(C18,'country region mapping'!$A$2:$A$267,'country region mapping'!$G$2:$G$267)} -> #NAME? | G18: 6.882 | H18: 34 | I18: 38 | J18: 13 | K18: 24 | L18: 68 | M18: 24 | N18: 10 | O18: 68 | P18: 53 | Q18: 24 | R18: 47 | S18: 88
A19: 2025 | B19: 18 | C19: Slovenia | D19: {=_xludf.XLOOKUP(C19,'country region mapping'!$A$2:$A$250, 'country region mapping'!$E$2:$E$250)} -> #NAME? | E19: {=_xludf.XLOOKUP(C19,'country region mapping'!$A$2:$A$267,'country region mapping'!$F$2:$F$267)} -> #NAME? | F19: {=_xludf.XLOOKUP(C19,'country region mapping'!$A$2:$A$267,'country region mapping'!$G$2:$G$267)} -> #NAME? | G19: 6.868 | H19: 25 | I19: 17 | J19: 24 | K19: 23 | L19: 7 | M19: 39 | N19: 80 | O19: 95 | P19: 54 | Q19: 39 | R19: 44 | S19: 122
A20: 2025 | B20: 19 | C20: Austria | D20: {=_xludf.XLOOKUP(C20,'country region mapping'!$A$2:$A$250, 'country region mapping'!$E$2:$E$250)} -> #NAME? | E20: {=_xludf.XLOOKUP(C20,'country region mapping'!$A$2:$A$267,'country region mapping'!$F$2:$F$267)} -> #NAME? | F20: {=_xludf.XLOOKUP(C20,'country region mapping'!$A$2:$A$267,'country region mapping'!$G$2:$G$267)} -> #NAME? | G20: 6.845 | H20: 24 | I20: 47 | J20: 11 | K20: 19 | L20: 53 | M20: 11 | N20: 18 | O20: 48 | P20: 39 | Q20: 11 | R20: 33 | S20: 76
A21: 2025 | B21: 21 | C21: United Arab Emirates | D21: {=_xludf.XLOOKUP(C21,'country region mapping'!$A$2:$A$250, 'country region mapping'!$E$2:$E$250)} -> #NAME? | E21: {=_xludf.XLOOKUP(C21,'country region mapping'!$A$2:$A$267,'country region mapping'!$F$2:$F$267)} -> #NAME? | F21: {=_xludf.XLOOKUP(C21,'country region mapping'!$A$2:$A$267,'country region mapping'!$G$2:$G$267)} -> #NAME? | G21: 6.821 | H21: 66 | I21: 104 | J21: 8 | K21: 30 | L21: 4 | M21: 19 | O21: 69 | P21: 56 | Q21: 19 | R21: 28 | S21: 77
A22: 2025 | B22: 20 | C22: Czechia | D22: {=_xludf.XLOOKUP(C22,'country region mapping'!$A$2:$A$250, 'country region mapping'!$E$2:$E$250)} -> #NAME? | E22: {=_xludf.XLOOKUP(C22,'country region mapping'!$A$2:$A$267,'country region mapping'!$F$2:$F$267)} -> #NAME? | F22: {=_xludf.XLOOKUP(C22,'country region mapping'!$A$2:$A$267,'country region mapping'!$G$2:$G$267)} -> #NAME? | G22: 6.821 | H22: 48 | I22: 15 | J22: 23 | K22: 36 | L22: 23 | M22: 38 | N22: 104 | O22: 26 | P22: 89 | Q22: 38 | R22: 57 | S22: 65
A23: 2025 | B23: 22 | C23: Saudi Arabia | D23: {=_xludf.XLOOKUP(C23,'country region mapping'!$A$2:$A$250, 'country region mapping'!$E$2:$E$250)} -> #NAME? | E23: {=_xludf.XLOOKUP(C23,'country region mapping'!$A$2:$A$267,'country region mapping'!$F$2:$F$267)} -> #NAME? | F23: {=_xludf.XLOOKUP(C23,'country region mapping'!$A$2:$A$267,'country region mapping'!$G$2:$G$267)} -> #NAME? | G23: 6.817 | H23: 59 | I23: 53 | J23: 14 | K23: 38 | M23: 55 | O23: 23 | P23: 19 | Q23: 55 | R23: 99 | S23: 66
A24: 2025 | B24: 23 | C24: United States | D24: {=_xludf.XLOOKUP(C24,'country region mapping'!$A$2:$A$267,'country region mapping'!$E$2:$E$267)} -> #NAME? | E24: {=_xludf.XLOOKUP(C24,'country region mapping'!$A$2:$A$267,'country region mapping'!$F$2:$F$267)} -> #NAME? | F24: {=_xludf.XLOOKUP(C24,'country region mapping'!$A$2:$A$267,'country region mapping'!$G$2:$G$267)} -> #NAME? | G24: 6.816 | H24: 6 | I24: 22 | J24: 5 | K24: 56 | L24: 104 | M24: 16 | N24: 48 | O24: 25 | P24: 32 | Q24: 16 | R24: 12 | S24: 25
A25: 2025 | B25: 24 | C25: Poland | D25: {=_xludf.XLOOKUP(C25,'country region mapping'!$A$2:$A$250, 'country region mapping'!$E$2:$E$250)} -> #NAME? | E25: {=_xludf.XLOOKUP(C25,'country region mapping'!$A$2:$A$267,'country region mapping'!$F$2:$F$267)} -> #NAME? | F25: {=_xludf.XLOOKUP(C25,'country region mapping'!$A$2:$A$267,'country region mapping'!$G$2:$G$267)} -> #NAME? | G25: 6.768 | H25: 3 | I25: 42 | J25: 29 | K25: 40 | L25: 49 | M25: 119 | N25: 30 | O25: 107 | P25: 4 | Q25: 119 | R25: 136 | S25: 139
A26: 2025 | B26: 25 | C26: Canada | D26: {=_xludf.XLOOKUP(C26,'country region mapping'!$A$2:$A$250, 'country region mapping'!$E$2:$E$250)} -> #NAME? | E26: {=_xludf.XLOOKUP(C26,'country region mapping'!$A$2:$A$267,'country region mapping'!$F$2:$F$267)} -> #NAME? | F26: {=_xludf.XLOOKUP(C26,'country region mapping'!$A$2:$A$267,'country region mapping'!$G$2:$G$267)} -> #NAME? | G26: 6.741 | H26: 42 | I26: 20 | J26: 18 | K26: 21 | L26: 48 | M26: 12 | N26: 14 | O26: 38 | P26: 93 | Q26: 12 | R26: 23 | S26: 27
A27: 2025 | B27: 26 | C27: Taiwan Province of China | D27: {=_xludf.XLOOKUP(C27,'country region mapping'!$A$2:$A$267,'country region mapping'!$E$2:$E$267)} -> #NAME? | E27: {=_xludf.XLOOKUP(C27,'country region mapping'!$A$2:$A$267,'country region mapping'!$F$2:$F$267)} -> #NAME? | F27: {=_xludf.XLOOKUP(C27,'country region mapping'!$A$2:$A$267,'country region mapping'!$G$2:$G$267)} -> #NAME? | G27: 6.714 | H27: 23 | I27: 61 | L27: 90 | M27: 42 | N27: 42 | O27: 34 | P27: 3 | Q27: 42 | R27: 98 | S27: 67
A28: 2025 | B28: 27 | C28: Belize | D28: {=_xludf.XLOOKUP(C28,'country region mapping'!$A$2:$A$250, 'country region mapping'!$E$2:$E$250)} -> #NAME? | E28: {=_xludf.XLOOKUP(C28,'country region mapping'!$A$2:$A$267,'country region mapping'!$F$2:$F$267)} -> #NAME? | F28: {=_xludf.XLOOKUP(C28,'country region mapping'!$A$2:$A$267,'country region mapping'!$G$2:$G$267)} -> #NAME? | G28: 6.711
A29: 2025 | B29: 28 | C29: Lithuania | D29: {=_xludf.XLOOKUP(C29,'country region mapping'!$A$2:$A$250, 'country region mapping'!$E$2:$E$250)} -> #NAME? | E29: {=_xludf.XLOOKUP(C29,'country region mapping'!$A$2:$A$267,'country region mapping'!$F$2:$F$267)} -> #NAME? | F29: {=_xludf.XLOOKUP(C29,'country region mapping'!$A$2:$A$267,'country region mapping'!$G$2:$G$267)} -> #NAME? | G29: 6.704 | H29: 47 | I29: 33 | J29: 27 | K29: 52 | L29: 59 | M29: 66 | N29: 59 | O29: 87 | P29: 35 | Q29: 66 | R29: 54 | S29: 46
A30: 2025 | B30: 29 | C30: United Kingdom | D30: {=_xludf.XLOOKUP(C30,'country region mapping'!$A$2:$A$267,'country region mapping'!$E$2:$E$267)} -> #NAME? | E30: {=_xludf.XLOOKUP(C30,'country region mapping'!$A$2:$A$267,'country region mapping'!$F$2:$F$267)} -> #NAME? | F30: {=_xludf.XLOOKUP(C30,'country region mapping'!$A$2:$A$267,'country region mapping'!$G$2:$G$267)} -> #NAME? | G30: 6.694 | H30: 50 | I30: 46 | J30: 21 | K30: 25 | L30: 89 | M30: 5 | N30: 23 | O30: 63 | P30: 78 | Q30: 5 | R30: 29 | S30: 64
A31: 2025 | B31: 30 | C31: Serbia | D31: {=_xludf.XLOOKUP(C31,'country region mapping'!$A$2:$A$250, 'country region mapping'!$E$2:$E$250)} -> #NAME? | E31: {=_xludf.XLOOKUP(C31,'country region mapping'!$A$2:$A$267,'country region mapping'!$F$2:$F$267)} -> #NAME? | F31: {=_xludf.XLOOKUP(C31,'country region mapping'!$A$2:$A$267,'country region mapping'!$G$2:$G$267)} -> #NAME? | G31: 6.691 | H31: 26 | I31: 8 | J31: 50 | K31: 57 | L31: 71 | M31: 40 | N31: 103 | O31: 124 | P31: 38 | Q31: 40 | R31: 126 | S31: 115
A32: 2025 | B32: 31 | C32: Uruguay | D32: {=_xludf.XLOOKUP(C32,'country region mapping'!$A$2:$A$250, 'country region mapping'!$E$2:$E$250)} -> #NAME? | E32: {=_xludf.XLOOKUP(C32,'country region mapping'!$A$2:$A$267,'country region mapping'!$F$2:$F$267)} -> #NAME? | F32: {=_xludf.XLOOKUP(C32,'country region mapping'!$A$2:$A$267,'country region mapping'!$G$2:$G$267)} -> #NAME? | G32: 6.635 | H32: 56 | I32: 35 | J32: 45 | K32: 45 | L32: 28 | M32: 86 | N32: 33 | O32: 36 | P32: 69 | Q32: 86 | R32: 100 | S32: 47
A33: 2025 | B33: 32 | C33: Brazil | D33: {=_xludf.XLOOKUP(C33,'country region mapping'!$A$2:$A$250, 'country region mapping'!$E$2:$E$250)} -> #NAME? | E33: {=_xludf.XLOOKUP(C33,'country region mapping'!$A$2:$A$267,'country region mapping'!$F$2:$F$267)} -> #NAME? | F33: {=_xludf.XLOOKUP(C33,'country region mapping'!$A$2:$A$267,'country region mapping'!$G$2:$G$267)} -> #NAME? | G33: 6.634 | H33: 94 | I33: 52 | J33: 62 | K33: 75 | L33: 57 | M33: 99 | N33: 67 | O33: 65 | P33: 103 | Q33: 99 | R33: 85 | S33: 89
A34: 2025 | B34: 33 | C34: Kazakhstan | D34: {=_xludf.XLOOKUP(C34,'country region mapping'!$A$2:$A$250, 'country region mapping'!$E$2:$E$250)} -> #NAME? | E34: {=_xludf.XLOOKUP(C34,'country region mapping'!$A$2:$A$267,'country region mapping'!$F$2:$F$267)} -> #NAME? | F34: {=_xludf.XLOOKUP(C34,'country region mapping'!$A$2:$A$267,'country region mapping'!$G$2:$G$267)} -> #NAME? | G34: 6.633 | H34: 21 | I34: 4 | J34: 42 | K34: 77 | L34: 62 | M34: 29 | N34: 74 | O34: 62 | P34: 2 | Q34: 29 | R34: 113 | S34: 98
A35: 2025 | B35: 34 | C35: Romania | D35: {=_xludf.XLOOKUP(C35,'country region mapping'!$A$2:$A$250, 'country region mapping'!$E$2:$E$250)} -> #NAME? | E35: {=_xludf.XLOOKUP(C35,'country region mapping'!$A$2:$A$267,'country region mapping'!$F$2:$F$267)} -> #NAME? | F35: {=_xludf.XLOOKUP(C35,'country region mapping'!$A$2:$A$267,'country region mapping'!$G$2:$G$267)} -> #NAME? | G35: 6.629 | H35: 54 | I35: 84 | J35: 35 | K35: 58 | L35: 70 | M35: 109 | N35: 112 | O35: 83 | P35: 58 | Q35: 109 | R35: 129 | S35: 120
A36: 2025 | B36: 35 | C36: France | D36: {=_xludf.XLOOKUP(C36,'country region mapping'!$A$2:$A$250, 'country region mapping'!$E$2:$E$250)} -> #NAME? | E36: {=_xludf.XLOOKUP(C36,'country region mapping'!$A$2:$A$267,'country region mapping'!$F$2:$F$267)} -> #NAME? | F36: {=_xludf.XLOOKUP(C36,'country region mapping'!$A$2:$A$267,'country region mapping'!$G$2:$G$267)} -> #NAME? | G36: 6.586 | H36: 36 | I36: 40 | J36: 19 | K36: 14 | L36: 114 | M36: 63 | N36: 31 | O36: 80 | P36: 74 | Q36: 63 | R36: 30 | S36: 127
A37: 2025 | B37: 36 | C37: Singapore | D37: {=_xludf.XLOOKUP(C37,'country region mapping'!$A$2:$A$250, 'country region mapping'!$E$2:$E$250)} -> #NAME? | E37: {=_xludf.XLOOKUP(C37,'country region mapping'!$A$2:$A$267,'country region mapping'!$F$2:$F$267)} -> #NAME? | F37: {=_xludf.XLOOKUP(C37,'country region mapping'!$A$2:$A$267,'country region mapping'!$G$2:$G$267)} -> #NAME? | G37: 6.585 | H37: 22 | I37: 48 | K37: 1 | L37: 41 | M37: 18 | N37: 1 | O37: 56 | P37: 18 | Q37: 18 | R37: 35 | S37: 58
A38: 2025 | B38: 37 | C38: El Salvador | D38: {=_xludf.XLOOKUP(C38,'country region mapping'!$A$2:$A$250, 'country region mapping'!$E$2:$E$250)} -> #NAME? | E38: {=_xludf.XLOOKUP(C38,'country region mapping'!$A$2:$A$267,'country region mapping'!$F$2:$F$267)} -> #NAME? | F38: {=_xludf.XLOOKUP(C38,'country region mapping'!$A$2:$A$267,'country region mapping'!$G$2:$G$267)} -> #NAME? | G38: 6.578 | H38: 72 | I38: 93 | J38: 83 | K38: 73 | L38: 16 | M38: 130 | N38: 19 | O38: 10 | P38: 62 | Q38: 130 | R38: 89 | S38: 93
A39: 2025 | B39: 38 | C39: Italy | D39: {=_xludf.XLOOKUP(C39,'country region mapping'!$A$2:$A$250, 'country region mapping'!$E$2:$E$250)} -> #NAME? | E39: {=_xludf.XLOOKUP(C39,'country region mapping'!$A$2:$A$267,'country region mapping'!$F$2:$F$267)} -> #NAME? | F39: {=_xludf.XLOOKUP(C39,'country region mapping'!$A$2:$A$267,'country region mapping'!$G$2:$G$267)} -> #NAME? | G39: 6.574 | H39: 19 | I39: 50 | J39: 20 | K39: 13 | L39: 122 | M39: 49 | N39: 99 | O39: 70 | P39: 100 | Q39: 49 | R39: 81 | S39: 81
A40: 2025 | B40: 39 | C40: Panama | D40: {=_xludf.XLOOKUP(C40,'country region mapping'!$A$2:$A$250, 'country region mapping'!$E$2:$E$250)} -> #NAME? | E40: {=_xludf.XLOOKUP(C40,'country region mapping'!$A$2:$A$267,'country region mapping'!$F$2:$F$267)} -> #NAME? | F40: {=_xludf.XLOOKUP(C40,'country region mapping'!$A$2:$A$267,'country region mapping'!$G$2:$G$267)} -> #NAME? | G40: 6.547 | H40: 107 | I40: 39 | J40: 41 | K40: 33 | L40: 56 | M40: 102 | N40: 121 | O40: 8 | P40: 33 | Q40: 102 | R40: 69 | S40: 70
...

Sheet country region mapping
A1: name | B1: Country code | C1: country-code | D1: iso_3166-2 | E1: region | F1: sub-region | G1: intermediate-region | I1: source:
A2: Afghanistan | B2: AF | C2: 4 | D2: ISO 3166-2:AF | E2: Asia | F2: Southern Asia | I2: https://github.com/lukes/ISO-3166-Countries-with-Regional-Codes/blob/master/all/all.csv
A3: Åland Islands | B3: AX | C3: 248 | D3: ISO 3166-2:AX | E3: Europe | F3: Northern Europe
A4: Albania | B4: AL | C4: 8 | D4: ISO 3166-2:AL | E4: Europe | F4: Southern Europe
A5: Algeria | B5: DZ | C5: 12 | D5: ISO 3166-2:DZ | E5: Africa | F5: Northern Africa
A6: American Samoa | B6: AS | C6: 16 | D6: ISO 3166-2:AS | E6: Oceania | F6: Polynesia
A7: Andorra | B7: AD | C7: 20 | D7: ISO 3166-2:AD | E7: Europe | F7: Southern Europe
A8: Angola | B8: AO | C8: 24 | D8: ISO 3166-2:AO | E8: Africa | F8: Sub-Saharan Africa | G8: Middle Africa
A9: Anguilla | B9: AI | C9: 660 | D9: ISO 3166-2:AI | E9: Americas | F9: Latin America and the Caribbean | G9: Caribbean
A10: Antarctica | B10: AQ | C10: 10 | D10: ISO 3166-2:AQ
A11: Antigua and Barbuda | B11: AG | C11: 28 | D11: ISO 3166-2:AG | E11: Americas | F11: Latin America and the Caribbean | G11: Caribbean
A12: Argentina | B12: AR | C12: 32 | D12: ISO 3166-2:AR | E12: Americas | F12: Latin America and the Caribbean | G12: South America
A13: Armenia | B13: AM | C13: 51 | D13: ISO 3166-2:AM | E13: Asia | F13: Western Asia
A14: Aruba | B14: AW | C14: 533 | D14: ISO 3166-2:AW | E14: Americas | F14: Latin America and the Caribbean | G14: Caribbean
A15: Australia | B15: AU | C15: 36 | D15: ISO 3166-2:AU | E15: Oceania | F15: Australia and New Zealand
A16: Austria | B16: AT | C16: 40 | D16: ISO 3166-2:AT | E16: Europe | F16: Western Europe
A17: Azerbaijan | B17: AZ | C17: 31 | D17: ISO 3166-2:AZ | E17: Asia | F17: Western Asia
A18: Bahamas | B18: BS | C18: 44 | D18: ISO 3166-2:BS | E18: Americas | F18: Latin America and the Caribbean | G18: Caribbean
A19: Bahrain | B19: BH | C19: 48 | D19: ISO 3166-2:BH | E19: Asia | F19: Western Asia
A20: Bangladesh | B20: BD | C20: 50 | D20: ISO 3166-2:BD | E20: Asia | F20: Southern Asia
A21: Barbados | B21: BB | C21: 52 | D21: ISO 3166-2:BB | E21: Americas | F21: Latin America and the Caribbean | G21: Caribbean
A22: Belarus | B22: BY | C22: 112 | D22: ISO 3166-2:BY | E22: Europe | F22: Eastern Europe
A23: Belgium | B23: BE | C23: 56 | D23: ISO 3166-2:BE | E23: Europe | F23: Western Europe
A24: Belize | B24: BZ | C24: 84 | D24: ISO 3166-2:BZ | E24: Americas | F24: Latin America and the Caribbean | G24: Central America
A25: Benin | B25: BJ | C25: 204 | D25: ISO 3166-2:BJ | E25: Africa | F25: Sub-Saharan Africa | G25: Western Africa
A26: Bermuda | B26: BM | C26: 60 | D26: ISO 3166-2:BM | E26: Americas | F26: Northern America
A27: Bhutan | B27: BT | C27: 64 | D27: ISO 3166-2:BT | E27: Asia | F27: Southern Asia
A28: Bolivia, Plurinational State of | B28: BO | C28: 68 | D28: ISO 3166-2:BO | E28: Americas | F28: Latin America and the Caribbean | G28: South America
A29: Bonaire, Sint Eustatius and Saba | B29: BQ | C29: 535 | D29: ISO 3166-2:BQ | E29: Americas | F29: Latin America and the Caribbean | G29: Caribbean
A30: Bosnia and Herzegovina | B30: BA | C30: 70 | D30: ISO 3166-2:BA | E30: Europe | F30: Southern Europe
A31: Botswana | B31: BW | C31: 72 | D31: ISO 3166-2:BW | E31: Africa | F31: Sub-Saharan Africa | G31: Southern Africa
A32: Bouvet Island | B32: BV | C32: 74 | D32: ISO 3166-2:BV | E32: Americas | F32: Latin America and the Caribbean | G32: South America
A33: Brazil | B33: BR | C33: 76 | D33: ISO 3166-2:BR | E33: Americas | F33: Latin America and the Caribbean | G33: South America
A34: British Indian Ocean Territory | B34: IO | C34: 86 | D34: ISO 3166-2:IO | E34: Africa | F34: Sub-Saharan Africa | G34: Eastern Africa
A35: Brunei Darussalam | B35: BN | C35: 96 | D35: ISO 3166-2:BN | E35: Asia | F35: South-eastern Asia
A36: Bulgaria | B36: BG | C36: 100 | D36: ISO 3166-2:BG | E36: Europe | F36: Eastern Europe
A37: Burkina Faso | B37: BF | C37: 854 | D37: ISO 3166-2:BF | E37: Africa | F37: Sub-Saharan Africa | G37: Western Africa
A38: Burundi | B38: BI | C38: 108 | D38: ISO 3166-2:BI | E38: Africa | F38: Sub-Saharan Africa | G38: Eastern Africa
A39: Cabo Verde | B39: CV | C39: 132 | D39: ISO 3166-2:CV | E39: Africa | F39: Sub-Saharan Africa | G39: Western Africa
A40: Cambodia | B40: KH | C40: 116 | D40: ISO 3166-2:KH | E40: Asia | F40: South-eastern Asia
...

Sheet jdr
A1: Date | B1: Happiness Rating (110) | C1: Practiced Fiddle? | D1: Practiced a Language? | E1: Slept 8 Hours? | F1: Meditated? | G1: Exercised?
A2: 45842 | B2: 7 | C2: Yes | D2: No | E2: No | F2: Yes | G2: Yes
A3: 45843 | B3: 7 | C3: No | D3: Yes | E3: Yes | F3: No | G3: No
A4: 45844 | B4: 6.5 | C4: Yes | D4: No | E4: No | F4: Yes | G4: Yes
A5: 45845 | B5: 7.5 | C5: Yes | D5: Yes | E5: No | F5: No | G5: No
A6: 45846 | B6: 6 | C6: No | D6: No | E6: Yes | F6: No | G6: No
A7: 45847 | B7: 7.5 | C7: No | D7: Yes | E7: No | F7: No | G7: No
A8: 45848 | B8: 8 | C8: No | D8: No | E8: No | F8: No | G8: No
A9: 45849 | B9: 8 | C9: No | D9: Yes | E9: No | F9: No | G9: No
A10: 45850 | B10: 8 | C10: No | D10: No | E10: Yes | F10: No | G10: No
A11: 45851 | B11: 8 | C11: No | D11: No | E11: Yes | F11: No | G11: No
A12: 45852 | B12: 9 | C12: No | D12: No | E12: Yes | F12: No | G12: No
A13: 45853 | B13: 9 | C13: No | D13: No | E13: Yes | F13: No | G13: No
... A261: 46112 | B261: 7 | C261: No | D261: Yes | E261: Yes | F261: No | G261: No

Sheet jdr_habitavgs
A1: Habit | B1: Happiness Score (avg) | C1: Days Practiced
A2: Practiced Fiddle? | B2: 6.2724138 | C2: =COUNTIF(jdr!C2:C261,"Yes") -> 87
A3: Practiced a Language? | B3: 6.6181818 | C3: =COUNTIF(jdr!D1:D261,"Yes") -> 44
A4: Slept 8 Hours? | B4: 6.2357798 | C4: =COUNTIF(jdr!E2:E261,"Yes") -> 109
A5: Meditated? | B5: 6.2321429 | C5: =COUNTIF(jdr!F1:F261,"Yes") -> 29
A6: Exercised? | B6: 6.2735849 | C6: =COUNTIF(jdr!G2:G261,"Yes") -> 54
